Workbook

Sheet Base de Dados FORMS
A1: Carimbo de data/hora | B1: 1) Este é um lugar (ambiente físico) agradável para trabalhar. | C1: 1) Gostaria de deixar um comentário sobre? | D1: 2) Eu recebo os equipamentos e recursos necessários para realizar o meu trabalho. | E1: 2) Gostaria de deixar um comentário sobre? | F1: 3) As pessoas aqui estão dispostas a fazer um pouco além da sua obrigação para concluir um trabalho. | G1: 3) Gostaria de deixar um comentário sobre? | H1: 4) Pode-se contar com a colaboração das pessoas por aqui. | I1: 4) Gostaria de deixar um comentário sobre? | J1: 5) A empresa oferece treinamentos ou oportunidades de desenvolvimento para o meu crescimento profissional. | K1: 5) Gostaria de deixar um comentário sobre? | L1: 6) Você tem uma visão clara de para onde estamos indo (futuro da empresa) e como fazer para chegar lá. | M1: 6) Gostaria de deixar um comentário sobre? | N1: 7) A empresa demonstra reconhecimento pelo bom trabalho e pelo esforço extra. | O1: 7) Gostaria de deixar um comentário sobre? | P1: 8) As pessoas aqui nesta empresa são remuneradas adequadamente em relação a outras empresas do mesmo segmento de mercado. | Q1: 8) Gostaria de deixar um comentário sobre? | R1: 9) Meu trabalho tem um sentido especial. Para mim, não é só “mais um emprego”. | S1: 9) Gostaria de deixar um comentário sobre? | T1: 10) Quando é contratado um funcionário novo, as pessoas fazem com que ele se sinta bem-vindo. | U1: 10) Gostaria de deixar um comentário sobre? | V1: 11) Tenho orgulho de contar com as pessoas que trabalho aqui. | W1: 11) Gostaria de deixar um comentário sobre? | X1: 12) As pessoas aqui têm vontade de vir para o trabalho. | Y1: 12) Gostaria de deixar um comentário sobre? | Z1: 13) Eu me sinto à vontade na empresa, sem precisar fingir que sou outra pessoa. | AA1: 13) Gostaria de deixar um comentário sobre? | AB1: 14) Existem canais de comunicação bem definidos para que os colaboradores possam expressar suas sugestões e reivindicações. | AC1: 14) Gostaria de deixar um comentário sobre? | AD1: 15) Você acredita que a empresa só promoveria uma demissão em massa como último recurso. | AE1: 15) Gostaria de deixar um comentário sobre? | AF1: 16) As pessoas são encorajadas a equilibrar sua vida profissional e pessoal. | AG1: 16) Gostaria de deixar um comentário sobre? | AH1: 17) Você sabe com clareza quem é seu líder (superior imediato). | AI1: 17) Gostaria de deixar um comentário sobre? | AJ1: 18) O seu líder (superior imediato) deixa claro o que ele espera do seu trabalho. | AK1: 18) Gostaria de deixar um comentário sobre? | AL1: 19) O seu líder demonstra comprometimento com o negócio da empresa (interesse no crescimento da empresa). | AM1: 19) Gostaria de deixar um comentário sobre? | AN1: 20) O seu líder é honesto e ético na condução dos negócios. | AO1: 20) Gostaria de deixar um comentário sobre? | AP1: 21) O seu líder demonstra interesse sincero por você como pessoa e não somente como empregado. | AQ1: 21) Gostaria de deixar um comentário sobre? | AR1: 22) É fácil se aproximar do seu líder e é também fácil de falar com ele. | AS1: 22) Gostaria de deixar um comentário sobre? | AT1: 23) O seu líder treina as pessoas com o foco nas suas necessidades. | AU1: 23) Gostaria de deixar um comentário sobre? | AV1: 24) O seu líder reconhece os erros como oportunidades de aprendizado. | AW1: 24) Gostaria de deixar um comentário sobre? | AX1: 25) O seu líder demonstra interesse nas ideias e sugestões que você e seus companheiros apresentam e toma ações com base nelas. | AY1: 25) Gostaria de deixar um comentário sobre? | AZ1: 26) O seu líder lhe mantém informado sobre assuntos importantes e sobre mudanças na empresa. | BA1: 26) Gostaria de deixar um comentário sobre? | BB1: 27) O seu líder tem uma visão clara de para onde estamos indo (futuro da empresa) e o que fazer para chegar lá. | BC1: 27) Gostaria de deixar um comentário sobre? | BD1: 28) O seu líder confia no bom trabalho das pessoas sem precisar vigiá-las. | BE1: 28) Gostaria de deixar um comentário sobre? | BF1: 29) O seu líder envolve as pessoas em decisões que afetam atividades e seu ambiente de trabalho. | BG1: 29) Gostaria de deixar um comentário sobre? | BH1: 30) O seu líder trata todos da mesma forma, sem proteger ninguém. | BI1: 30) Gostaria de deixar um comentário sobre? | BJ1: 31) O seu líder sabe coordenar pessoas e distribuir tarefas adequadamente. | BK1: 31) Gostaria de deixar um comentário sobre? | BL1: 32) O seu líder dá autonomia às pessoas. | BM1: 32) Gostaria de deixar um comentário sobre? | BN1: 33) O seu líder age de acordo com o que fala. | BO1: 33) Gostaria de deixar um comentário sobre? | BP1: 34) O seu líder dá feedback (crítica construtiva) sobre o desempenho de seu trabalho. | BQ1: 34) Gostaria de deixar um comentário sobre? | BR1: 35) As pessoas aqui na empresa são bem tratadas independentemente da sua idade, cor, religião ou sexo. | BS1: 35) Gostaria de deixar um comentário sobre? | BT1: 36) Você alguma vez já foi humilhado pelo seu líder ou presenciou alguma humilhação. | BU1: 36) Gostaria de deixar um comentário sobre? | BV1: 37) Aqui as pessoas se importam umas com as outras. | BW1: 37) Gostaria de deixar um comentário sobre? | BX1: 38) Existe um sentimento de equipe por aqui. | BY1: 38) Gostaria de deixar um comentário sobre? | BZ1: 39) Nós sempre comemoramos as metas atingidas e os eventos especiais. | CA1: 39) Gostaria de deixar um comentário sobre? | CB1: 40) As pessoas fazem “politicagem” (puxa saco) como forma de obter resultados. | CC1: 40) Gostaria de deixar um comentário sobre? | CD1: 41) A Diretoria da empresa é aberta a sugestões e é fácil falar com ela. | CE1: 41) Gostaria de deixar um comentário sobre? | CF1: 42) Você tem um bom relacionamento com a Diretoria da empresa. | CG1: 42) Gostaria de deixar um comentário sobre? | CH1: 43) Eu sou bem tratado, independente de minha função na empresa. | CI1: 43) Gostaria de deixar um comentário sobre? | CJ1: 44) Sinto que sou valorizado aqui e que posso fazer a diferença. | CK1: 44) Gostaria de deixar um comentário sobre? | CL1: 45) Este é um lugar agradável para se trabalhar. | CM1: 45) Gostaria de deixar um comentário sobre? | CN1: 46) Existe fofoca por aqui. | CO1: 46) Gostaria de deixar um comentário sobre? | CP1: 47) Percebo um clima de rivalidade (competição interna) aqui. | CQ1: 47) Gostaria de deixar um comentário sobre? | CR1: 48) Pretendo trabalhar aqui ainda por muito tempo. | CS1: 48) Gostaria de deixar um comentário sobre? | CT1: 49) Existe um bom relacionamento entre as áreas da empresa (equipes das diferentes expertises de conhecimento). | CU1: 49) Gostaria de deixar um comentário sobre? | CV1: 50) Levando-se tudo em conta, eu diria que este é um excelente lugar para trabalhar. | CW1: 50) Gostaria de deixar um comentário sobre? | CX1: 51) Marque os TRÊS (03) benefícios que você julga mais importantes , independente se a empresa oferece ou não. | CY1: 51) Gostaria de deixar um comentário sobre? | CZ1: 52) Cite 3 (três) PONTOS FORTES DA EMPRESA (o que já é bom na empresa). | DA1: 53) Cite 3 (três) PONTOSDE MELHORIA DA EMPRESA (o que ainda precisa ser mudado na empresa). | DB1: 54) Este espaço é seu, use-o para registrar comentários e sugestões não abordados anteriormente.
A2: 45687.339 | B2: Concordo Sempre | D2: Concordo | F2: Concordo Sempre | H2: Concordo | J2: Concordo | L2: Concordo Sempre | N2: Concordo | P2: Discordo | Q2: Eu acho q poderíamos melhorar o salário pq hoje ao nosso redor tudo está muito acima do preço e a dificuldade aumenta,Em relação aos benefícios, acho q poderíamos melhorar o vale alimentação, pq hoje em dia um almoço custa em torno de 21$ , poderíamos melhorar também em questão de vale academia | R2: Concordo | S2: Procuro crescer e acrescentar profissionalismo dentro da família nordeste | T2: Concordo | V2: Concordo | X2: Concordo | Z2: Concordo | AB2: Concordo Sempre | AC2: Nosso supervisor nos dá a liberdade de expressar ideias e opiniões para a melhora do dia a dia | AD2: Discordo | AE2: Acho q a empresa deve tomar a decisão de demissão a partir do momento q a pessoa não se dispõe a cumprir seu dever como ctl | AF2: Concordo Sempre | AH2: Concordo Sempre | AI2: Sim, um cara mente aberta e muito parceiro de serviço de todas as horas | AJ2: Concordo Sempre | AK2: Não só deixa claro, como ajuda a melhorar todos os dias | AL2: Concordo Sempre | AM2: Visão plena em relação ao crescimento da família nordeste | AN2: Concordo Sempre | AP2: Concordo Sempre | AQ2: Sim, a ajuda é diária como pessoa e profissional | AR2: Concordo Sempre | AT2: Concordo | AV2: Concordo | AX2: Concordo | AZ2: Concordo | BB2: Concordo Sempre | BD2: Concordo | BF2: Concordo Sempre | BH2: Concordo | BJ2: Concordo Sempre | BL2: Concordo | BN2: Concordo Sempre | BP2: Concordo Sempre | BR2: Concordo Sempre | BT2: Concordo Sempre | BV2: Concordo Sempre | BX2: Concordo Sempre | BZ2: Concordo Sempre | CB2: Concordo | CD2: Concordo | CF2: Discordo | CG2: Ainda não conheci ainda a diretoria | CH2: Concordo | CJ2: Concordo | CL2: Concordo | CN2: Concordo | CP2: Concordo | CR2: Concordo | CT2: Concordo | CV2: Concordo | CW2: Lugar excelente pra trabalhar | CX2: Assistência Médica, Auxílio Combustível, Vale Alimentação, Empréstimo Consignado, Gympass (Convênio Academias) | CY2: Melhorais benefícios | CZ2: união, metodologia de trabalho, incentivo, | DA2: salário, vale alimentação, melhoria de benefícios.. | DB2: O vale academia ajudaria muito as pessoas q gostam de fazer Sport e incentiva a vida pessoal
A3: 45687.339 | B3: Concordo Sempre | C3: . | D3: Concordo Sempre | E3: . | F3: Concordo | G3: . | H3: Discordo | I3: De alguns,não de todos | J3: Concordo | K3: . | L3: Concordo Sempre | M3: . | N3: Concordo Sempre | O3: . | P3: Concordo Sempre | Q3: Sim | R3: Concordo Sempre | S3: Sim | T3: Concordo Sempre | U3: Sim | V3: Concordo Sempre | W3: Sim | X3: Discordo | Y3: Não todos | Z3: Concordo Sempre | AA3: Sim | AB3: Concordo Sempre | AC3: Sim | AD3: Concordo Sempre | AE3: Sim | AF3: Concordo | AG3: Sim | AH3: Concordo Sempre | AI3: Sim | AJ3: Concordo Sempre | AK3: Sim | AL3: Concordo Sempre | AM3: Sim | AN3: Concordo Sempre | AO3: Sim | AP3: Concordo Sempre | AQ3: Sim | AR3: Concordo Sempre | AS3: Muito acessível | AT3: Concordo Sempre | AU3: Sim | AV3: Concordo Sempre | AW3: Sim | AX3: Concordo Sempre | AY3: Sim | AZ3: Concordo Sempre | BA3: Sim | BB3: Concordo Sempre | BC3: Sim | BD3: Concordo Sempre | BE3: Sim | BF3: Discordo | BG3: Não | BH3: Concordo Sempre | BI3: Sim | BJ3: Concordo Sempre | BK3: Sim | BL3: Concordo | BM3: Na medida do possível | BN3: Concordo Sempre | BO3: Sim | BP3: Concordo Sempre | BQ3: Sim | BR3: Concordo Sempre | BS3: Sim | BT3: Discordo Sempre | BU3: Nunca | BV3: Concordo Sempre | BW3: Sim | BX3: Concordo Sempre | BY3: Sim | BZ3: Concordo Sempre | CA3: Sim | CB3: Discordo | CC3: Não | CD3: Concordo Sempre | CE3: Sim | CF3: Concordo Sempre | CG3: Sim | CH3: Concordo Sempre | CI3: Sim | CJ3: Concordo Sempre | CK3: Sim | CL3: Concordo Sempre | CM3: Sim | CN3: Concordo | CO3: Existe muitos fofoca por aqui | CP3: Discordo | CQ3: Não | CR3: Concordo Sempre | CS3: Sim | CT3: Concordo | CU3: Sim | CV3: Concordo Sempre | CW3: Sim sem dúvidas | CX3: Auxílio Combustível, Refeição na Empresa, Vale Refeição, Vale Alimentação, Cesta Básica | CY3: . | CZ3: Como eu sou tratado,pagamentos sem nem um dia de atraso e o convívio com todos. | DA3: Pra mim está indo tudo bem,não tem nada a melhorar no meu ver | DB3: Sucesso Nordeste!!!
A4: 45687.34 | B4: Concordo Sempre | C4: . | D4: Concordo Sempre | E4: . | F4: Concordo | G4: . | H4: Discordo | I4: De alguns,não de todos | J4: Concordo | K4: . | L4: Concordo Sempre | M4: . | N4: Concordo Sempre | O4: . | P4: Concordo Sempre | Q4: Sim | R4: Concordo Sempre | S4: Sim | T4: Concordo Sempre | U4: Sim | V4: Concordo Sempre | W4: Sim | X4: Discordo | Y4: Não todos | Z4: Concordo Sempre | AA4: Sim | AB4: Concordo Sempre | AC4: Sim | AD4: Concordo Sempre | AE4: Sim | AF4: Concordo | AG4: Sim | AH4: Concordo Sempre | AI4: Sim | AJ4: Concordo Sempre | AK4: Sim | AL4: Concordo Sempre | AM4: Sim | AN4: Concordo Sempre | AO4: Sim | AP4: Concordo Sempre | AQ4: Sim | AR4: Concordo Sempre | AS4: Muito acessível | AT4: Concordo Sempre | AU4: Sim | AV4: Concordo Sempre | AW4: Sim | AX4: Concordo Sempre | AY4: Sim | AZ4: Concordo Sempre | BA4: Sim | BB4: Concordo Sempre | BC4: Sim | BD4: Concordo Sempre | BE4: Sim | BF4: Discordo | BG4: Não | BH4: Concordo Sempre | BI4: Sim | BJ4: Concordo Sempre | BK4: Sim | BL4: Concordo | BM4: Na medida do possível | BN4: Concordo Sempre | BO4: Sim | BP4: Concordo Sempre | BQ4: Sim | BR4: Concordo Sempre | BS4: Sim | BT4: Discordo Sempre | BU4: Nunca | BV4: Concordo Sempre | BW4: Sim | BX4: Concordo Sempre | BY4: Sim | BZ4: Concordo Sempre | CA4: Sim | CB4: Discordo | CC4: Não | CD4: Concordo Sempre | CE4: Sim | CF4: Concordo Sempre | CG4: Sim | CH4: Concordo Sempre | CI4: Sim | CJ4: Concordo Sempre | CK4: Sim | CL4: Concordo Sempre | CM4: Sim | CN4: Concordo | CO4: Existe muitos fofoca por aqui | CP4: Discordo | CQ4: Não | CR4: Concordo Sempre | CS4: Sim | CT4: Concordo | CU4: Sim | CV4: Concordo Sempre | CW4: Sim sem dúvidas | CX4: Auxílio Combustível, Refeição na Empresa, Vale Refeição, Vale Alimentação, Cesta Básica | CY4: . | CZ4: Como eu sou tratado,pagamentos sem nem um dia de atraso e o convívio com todos. | DA4: Pra mim está indo tudo bem,não tem nada a melhorar no meu ver | DB4: Sucesso Nordeste!!!
A5: 45687.347 | B5: Concordo Sempre | C5: Me sinto muito bem trabalhando na Nordeste, aqui tem pessoas maravilhosas. | D5: Concordo | E5: . | F5: Concordo | G5: . | H5: Concordo | I5: . | J5: Discordo | K5: Já foi prometido alguns cursos para nosso desenvolvimento profissional, mas até o momento ainda não tivemos nenhum retorno sobre. | L5: Concordo Sempre | M5: . | N5: Concordo | O5: . | P5: Concordo | Q5: . | R5: Concordo Sempre | S5: Amo o que eu faço | T5: Concordo Sempre | U5: Aqui acolhemos todo mundo bem | V5: Concordo | W5: . | X5: Concordo | Y5: . | Z5: Concordo Sempre | AA5: . | AB5: Concordo | AC5: . | AD5: Concordo | AE5: . | AF5: Concordo | AG5: . | AH5: Concordo | AI5: . | AJ5: Concordo | AK5: . | AL5: Concordo | AM5: . | AN5: Concordo | AO5: . | AP5: Concordo | AQ5: . | AR5: Concordo Sempre | AS5: . | AT5: Concordo | AV5: Concordo | AX5: Concordo | AZ5: Concordo | BB5: Concordo | BD5: Concordo Sempre | BF5: Discordo | BG5: Não, não acontece | BH5: Concordo | BJ5: Concordo | BL5: Concordo | BN5: Concordo | BP5: Concordo | BR5: Concordo Sempre | BT5: Discordo Sempre | BU5: Nunca aconteceu nada desse tipo na empresa. | BV5: Concordo | BX5: Concordo | BZ5: Concordo Sempre | CB5: Concordo | CD5: Concordo | CF5: Concordo Sempre | CH5: Concordo | CJ5: Discordo | CK5: Me sinto desvalorizado pelas pessoas que trabalham aqui e não pela empresa. | CL5: Concordo | CN5: Concordo | CP5: Discordo | CQ5: Não temos rivalidade.. assim eu penso | CR5: Concordo | CT5: Concordo | CV5: Concordo | CW5: . | CX5: Assistência Médica, Auxílio Combustível, Multibenefícios Alimentação/ Refeição, Cesta Básica, Day Off | CY5: 1 | CZ5: Benefícios, salários em dia, somos livres para trabalhar. | DA5: Oportunidades de crescimento, reconhecer o esforço, escutar mais os colaboradores. | DB5: .
A6: 45687.347 | B6: Concordo | C6: . | D6: Concordo | E6: . | F6: Concordo | G6: . | H6: Concordo | I6: . | J6: Concordo | K6: . | L6: Concordo | M6: . | N6: Concordo | O6: . | P6: Concordo | Q6: . | R6: Concordo Sempre | S6: . | T6: Concordo Sempre | U6: . | V6: Concordo | W6: . | X6: Concordo | Y6: . | Z6: Concordo Sempre | AA6: . | AB6: Concordo | AC6: . | AD6: Concordo | AE6: . | AF6: Concordo | AG6: . | AH6: Concordo | AI6: . | AJ6: Concordo | AK6: . | AL6: Concordo Sempre | AM6: . | AN6: Concordo Sempre | AO6: . | AP6: Concordo Sempre | AQ6: . | AR6: Concordo Sempre | AS6: . | AT6: Concordo Sempre | AU6: . | AV6: Concordo | AW6: . | AX6: Concordo Sempre | AY6: . | AZ6: Concordo Sempre | BA6: . | BB6: Concordo Sempre | BC6: . | BD6: Concordo | BE6: . | BF6: Concordo Sempre | BG6: . | BH6: Concordo | BI6: . | BJ6: Concordo | BK6: . | BL6: Concordo | BM6: . | BN6: Concordo Sempre | BO6: . | BP6: Concordo Sempre | BQ6: . | BR6: Concordo Sempre | BS6: . | BT6: Discordo Sempre | BU6: Nunca. | BV6: Concordo | BW6: . | BX6: Concordo | BY6: . | BZ6: Concordo Sempre | CA6: . | CB6: Discordo | CC6: Não. | CD6: Concordo Sempre | CE6: . | CF6: Concordo Sempre | CG6: . | CH6: Concordo Sempre | CI6: . | CJ6: Concordo Sempre | CK6: . | CL6: Concordo Sempre | CM6: . | CN6: Discordo | CO6: Não no meu setor. | CP6: Concordo | CQ6: Em alguma situações. | CR6: Concordo Sempre | CS6: . | CT6: Concordo | CU6: . | CV6: Concordo Sempre | CW6: . | CX6: Assistência Médica, Assistência Odontológica, Auxílio Combustível, Vale Refeição, Vale Alimentação | CY6: . | CZ6: Agilidade,processos,convivência. | DA6: Sala comercial,área de descanso, variar mix de equipamentos. | DB6: humberto.aragao@nordesteloc.com.br
A7: 45687.348 | B7: Concordo | D7: Concordo | F7: Discordo Sempre | G7: Não vejo ninguém faz oq eu fasso além da minha obrigação | H7: Discordo | J7: Discordo Sempre | K7: Nunca tiver oportunidade aqui | L7: Concordo | N7: Discordo Sempre | O7: Pra mim não | P7: Concordo | R7: Concordo Sempre | T7: Discordo | U7: No começo sim mais depois não | V7: Discordo Sempre | X7: Concordo | Y7: Eu sim mais não sei as outras pessoas | Z7: Concordo Sempre | AB7: Discordo | AD7: Concordo | AF7: Concordo | AH7: Discordo | AJ7: Discordo | AL7: Discordo | AN7: Concordo | AP7: Discordo Sempre | AR7: Concordo Sempre | AT7: Discordo Sempre | AV7: Discordo | AX7: Discordo Sempre | AZ7: Concordo Sempre | BB7: Concordo Sempre | BD7: Discordo Sempre | BF7: Discordo Sempre | BH7: Discordo Sempre | BJ7: Discordo | BL7: Concordo | BN7: Discordo Sempre | BP7: Concordo | BR7: Concordo Sempre | BT7: Discordo Sempre | BU7: Sim muitos vezes | BV7: Discordo | BX7: Discordo Sempre | BZ7: Concordo Sempre | CB7: Discordo | CD7: Concordo Sempre | CF7: Concordo Sempre | CH7: Discordo Sempre | CI7: Minha função aqui e desvalorizada não pela empresa mais sim pela equipe de trabalho | CJ7: Discordo Sempre | CL7: Concordo Sempre | CN7: Discordo Sempre | CO7: Aqui só que tem e fofoca | CP7: Concordo | CR7: Concordo Sempre | CT7: Concordo | CV7: Concordo Sempre | CW7: Lugar e bom pra trabalhar mais as pessoas não | CX7: Assistência Médica, Assistência Odontológica, Vale Alimentação, Cesta Básica, Seguro de Vida | CY7: Os benefícios são bom mais queira outro | CZ7: Sem resposta | DA7: Não sei oq fala | DB7: Sem resposta
A8: 45687.349 | B8: Concordo Sempre | C8: . | D8: Concordo Sempre | E8: . | F8: Discordo Sempre | G8: Por mais que seja uma equipe pequena, infelizmente a maioria é dotado de uma política individualista, gerando muitas vezes inclusive conflitos e fugindo das responsabilidades de suas próprias funções | H8: Concordo | I8: . | J8: Concordo | K8: Sei que temos por obrigação apostar em nosso próprio conhecimento, através cursos por exemplo, mas seria interessante a empresa oferecer algo “fora da caixa”. Exemplo: um curso pago de alto nível em técnica de vendas para o setor comercial. | L8: Concordo Sempre | M8: . | N8: Concordo Sempre | O8: Uma das políticas da empresa de maior prestígio sem dúvida alguma é o reconhecimento! | P8: Concordo Sempre | Q8: . | R8: Concordo Sempre | S8: Tenho por natureza entregar excelência e dedicação em tudo que faço. | T8: Concordo | U8: . | V8: Discordo | W8: Nem todos são amigavelmente saudáveis | X8: Discordo | Y8: Tem pessoas que demonstram nitidamente não só pela aparência ao chegar na empresa, quanto pelas próprias palavras, a sua insatisfação | Z8: Concordo Sempre | AA8: . | AB8: Concordo Sempre | AC8: . | AD8: Concordo | AE8: . | AF8: Concordo Sempre | AG8: . | AH8: Concordo Sempre | AI8: . | AJ8: Concordo Sempre | AK8: . | AL8: Concordo Sempre | AM8: . | AN8: Concordo Sempre | AO8: . | AP8: Concordo Sempre | AQ8: Não só a mim como a todos. Sempre solicito, disposto a ajudar. Amigo de todos (até mesmo dos que não merecem) | AR8: Concordo Sempre | AS8: . | AT8: Concordo Sempre | AU8: . | AV8: Concordo | AW8: . | AX8: Concordo | AY8: . | AZ8: Concordo Sempre | BA8: . | BB8: Concordo Sempre | BC8: . | BD8: Concordo Sempre | BE8: Confia até demais. Poderia ser um pouco mais de malícia, pessoas erram e fazem coisas erradas quase que o tempo inteiro | BF8: Concordo Sempre | BG8: Sempre democrático | BH8: Concordo | BI8: . | BJ8: Concordo | BK8: . | BL8: Concordo | BM8: . | BN8: Concordo | BO8: . | BP8: Concordo Sempre | BQ8: . | BR8: Concordo Sempre | BS8: Empresa inclusiva em todos os campos | BT8: Discordo Sempre | BU8: Jamais presenciei | BV8: Discordo Sempre | BW8: A maioria das pessoas quando não podem ajudar, tentam prejudicar o colega | BX8: Discordo | BY8: Infelizmente por diversas vezes o individualismo prevalece | BZ8: Concordo Sempre | CA8: . | CB8: Discordo Sempre | CC8: Nunca presenciei | CD8: Concordo Sempre | CE8: Diretores sem acessíveis e dispostos a ouvirem | CF8: Concordo Sempre | CG8: . | CH8: Concordo Sempre | CI8: . | CJ8: Concordo | CK8: . | CL8: Concordo | CM8: . | CN8: Discordo Sempre | CO8: A fofoca na empresa Chega a ser cultural. | CP8: Concordo Sempre | CQ8: . | CR8: Discordo | CS8: No momento não consigo enxergar oportunidades além devido ao nosso próprio mercado (escasso infelizmente), e busco sempre crescimento na área profissional, não a tôa que me capacito constantemente para isso. | CT8: Concordo | CU8: . | CV8: Concordo | CW8: . | CX8: Assistência Médica, Assistência Odontológica, Auxílio Combustível, Multibenefícios Alimentação/ Refeição, Empréstimo Consignado | CY8: . | CZ8: Transparência, pontualidade salarial e inclusão. | DA8: Vale alimentação defasado, banco de horas individual (como sugestão) | DB8: Sugestão/solicitação que já foi realizada anteriormente porém não acatada: banheiros exclusivos individuais para homens e mulheres
A9: 45687.349 | B9: Concordo Sempre | C9: Ambiente Agradável | D9: Concordo | E9: Recebo. | F9: Discordo | G9: Alguns não., falta um pouco mais de comprimento de algumas pessoas para ajuda o próximo e para seu próprio crescimento. | H9: Concordo | I9: Porém, nem sempre. | J9: Discordo | K9: Em Relação a treinamentos poderíamos te um pouco mais, fazer parceiras com entidades de cursos profissionalizante. | L9: Concordo | M9: Crescimento gigantesco. | N9: Concordo | O9: As vezes. | P9: Concordo | Q9: Acredito que sim. | R9: Concordo Sempre | S9: Amo o que faço. | T9: Concordo Sempre | U9: Sim, com certeza | V9: Concordo | W9: Turma boa | X9: Concordo | Y9: Acredito que sim. | Z9: Concordo Sempre | AA9: Empresa leve, me sinto muito a vontade. | AB9: Concordo | AC9: As vezes. | AD9: Concordo Sempre | AE9: Espero que nunca aconteça | AF9: Concordo | AG9: Sim, porém depende de cada um | AH9: Concordo Sempre | AI9: Sim | AJ9: Concordo | AK9: Sim | AL9: Concordo | AM9: Sim | AN9: Concordo Sempre | AO9: Sim | AP9: Concordo Sempre | AQ9: Sim, se damos super bem | AR9: Concordo Sempre | AS9: Certeza | AT9: Concordo Sempre | AU9: Demais. | AV9: Concordo | AW9: Sim | AX9: Concordo | AY9: Sim | AZ9: Concordo Sempre | BA9: Sim | BB9: Concordo | BC9: Sim | BD9: Concordo Sempre | BE9: Sim | BF9: Concordo Sempre | BG9: Sim | BH9: Discordo | BI9: Não | BJ9: Discordo | BK9: Deixa a desejar um pouco na cobrança das atividades diárias. | BL9: Concordo Sempre | BM9: Demais. | BN9: Concordo | BO9: Sim | BP9: Concordo | BQ9: Sim sim | BR9: Concordo Sempre | BS9: Certeza | BT9: Discordo Sempre | BU9: Nunca | BV9: Concordo | BW9: Sim | BX9: Concordo | BY9: Sim | BZ9: Concordo Sempre | CA9: Sim | CB9: Discordo | CC9: Não | CD9: Concordo | CE9: Sim | CF9: Concordo Sempre | CG9: Muito. | CH9: Concordo Sempre | CI9: Sim | CJ9: Concordo | CK9: Sim | CL9: Concordo Sempre | CM9: Muito agradável | CN9: Concordo | CO9: As vezes | CP9: Concordo | CQ9: As vezes | CR9: Concordo Sempre | CS9: Sim | CT9: Concordo | CU9: Sim | CV9: Concordo Sempre | CW9: Ótimo | CX9: Assistência Médica, Assistência Odontológica, Auxílio Combustível, Vale Refeição, Auxílio Educação | CY9: Bons auxílios | CZ9: Empresa ótima de trabalho. Ambiente Agradável Fazemos o que e certo | DA9: Oportunidade de cursos Promoções | DB9: Tudo tranquilo.
A10: 45687.349 | B10: Concordo Sempre | D10: Concordo | E10: Mas poderia melhorar um pouco mas nós epis | F10: Concordo | H10: Concordo Sempre | J10: Concordo | L10: Concordo | N10: Discordo | O10: Acho q deveria ganhar um pouco mas na extra | P10: Concordo | R10: Concordo | S10: Ela saber reconhecer o trabalhador | T10: Concordo | V10: Concordo | X10: Discordo | Y10: Tem umas q vem arrastado | Z10: Concordo Sempre | AB10: Discordo | AD10: Concordo | AF10: Concordo Sempre | AH10: Concordo Sempre | AJ10: Concordo | AL10: Concordo Sempre | AM10: Sempre ajuda na evolução da empresa | AN10: Concordo Sempre | AP10: Concordo Sempre | AQ10: Sempre tenta ajudar os colaboradores da empresa | AR10: Concordo Sempre | AS10: Uma pessoa ótima | AT10: Concordo | AV10: Concordo | AX10: Concordo | AZ10: Concordo Sempre | BB10: Concordo | BD10: Concordo | BF10: Discordo | BH10: Concordo Sempre | BJ10: Concordo | BL10: Concordo | BN10: Concordo | BP10: Concordo Sempre | BR10: Concordo Sempre | BS10: Todos são tratados. Da msm forma | BT10: Discordo Sempre | BV10: Concordo | BW10: A maioria sim | BX10: Concordo | BZ10: Concordo Sempre | CB10: Concordo | CC10: Sempre tem uma pessoa q puxa o saco . | CD10: Discordo | CF10: Discordo | CH10: Concordo Sempre | CJ10: Concordo Sempre | CL10: Concordo | CN10: Concordo | CO10: Tem 2 q gosta de uma fofoca | CP10: Discordo | CR10: Concordo Sempre | CT10: Concordo | CV10: Concordo | CW10: Tudo mundo ajuda | CX10: Auxílio Combustível, Multibenefícios Alimentação/ Refeição, Auxílio Educação, Cesta Básica, Empréstimo Consignado | CY10: Seria muito bom nesses auxílio pra nós colaboradores | CZ10: Prestativa, oportunidade, evolução, | DA10: Salaria, ajuda de custo de combustível, auxílio alimentação | DB10: Muito obrigado pela oportunidade..mas ajude a melhorar nas nossas respostas
A11: 45687.35 | B11: Concordo | D11: Discordo | E11: A quantidade de fardamento é insuficiente, mecânicos e externo principalmente que suam mais e precisam lavar as fadas mais vezes em pouco tempo elas ficam desquitaras, velhas e com uma aparência ruim | F11: Discordo | G11: Existe sim pessoas que vc ver fazendo o além dando seu melhor mas tem algumas pessoas que fazem apenas o que é solicitado em seu cargo | H11: Concordo | J11: Discordo | K11: Cabe melhorias em relação a treinamentos, vejo que as pessoas que estão entrando por exemplo não tem treinamento nem sobre os equipamentos nem sobre os processos da empresa. | L11: Concordo | N11: Concordo | P11: Discordo Sempre | Q11: Em relação a remuneração vejo que as outras empresas no mercado pagam melhor, tanto fixo que chega ser uma diferença de 500,00 a menos distante , outro ponto seria a melhoria no valor da alimentação pois atualmente conseguimos até comprar a refeição mais algo pra beber e acompanhar não . Uma melhoria poderia ter um benefício de auxílio a academia outras empresas no mesmo segmento no mercado possui e é ideal para incentivar o funcionário a cuidar da saúde. | R11: Concordo Sempre | T11: Concordo | V11: Concordo | X11: Concordo | Z11: Concordo Sempre | AB11: Discordo | AC11: Cabe melhoria uma sugestão era ter um contato ouvidoria para que os funcionário pudessem expressar suas reivindicação, ideias e pedidos de ajuda. | AD11: Concordo | AF11: Concordo | AH11: Concordo Sempre | AJ11: Concordo Sempre | AL11: Concordo Sempre | AN11: Concordo Sempre | AP11: Concordo Sempre | AR11: Concordo | AT11: Discordo | AU11: Meu líder creio que não tem suporte para treinar quem vem chegando na empresa de colaborador novo e nem atualizações . | AV11: Concordo | AX11: Concordo | AZ11: Concordo | BB11: Concordo Sempre | BD11: Concordo | BF11: Concordo | BH11: Concordo | BJ11: Concordo | BL11: Concordo | BN11: Concordo | BP11: Concordo | BQ11: Meu líder está sempre chamando os funcionários para feedbook | BR11: Concordo Sempre | BT11: Discordo Sempre | BU11: Nunca vi o líder agir dessa forma | BV11: Discordo | BW11: Existe pessoas sim que se importam com as outras mas existe algumas que pensam somente em si | BX11: Concordo | BZ11: Concordo Sempre | CB11: Concordo | CD11: Concordo | CF11: Concordo | CH11: Concordo Sempre | CJ11: Concordo | CL11: Concordo | CN11: Discordo | CO11: Não vejo fofoca no sentido de prejudicar a empresa ou algum colaborador | CP11: Discordo | CQ11: Vejo aqui entre as áreas os colaboradores se ajudando | CR11: Concordo | CT11: Concordo | CV11: Concordo | CW11: Existem pontos de melhorias que creio que será ouvido e aos poucos trabalhados e por isso ainda sim é um lugar bom de se trabalhar | CX11: Assistência Médica, Multibenefícios Alimentação/ Refeição, Auxílio Educação, Gympass (Convênio Academias), Day Off | CY11: Creio que alguns benefício que ainda não possuímos são simples por exemplo o day off é um deles . | CZ11: Transparência. Pontualidade. Cordialidade. | DA11: Salário. Benefícios. Treinamentos. | DB11: Creio que a Nordeste tem total capacidade de melhoria tanto que essa pesquisa é um dos indícios disso uma empresa que está em crescimento ainda assim é uma boa empresa pra se trabalhar, indicaria como uma boa empresa porém as melhorias em relação a benefícios , salários e treinamentos são os mais importantes
A12: 45687.353 | B12: Concordo | D12: Concordo | F12: Concordo | H12: Concordo | J12: Concordo | L12: Concordo | N12: Concordo | P12: Discordo | Q12: Acredito que deva melhorar em relação aos benefícios, tipo aumentar o valor do vale refeição para 25,00 por dia, Vale cultura, Gim pés, vale combustível para quem tem veículo próprio mas não faz uso do vale transporte. | R12: Concordo | T12: Concordo | V12: Concordo | X12: Concordo | Z12: Concordo | AB12: Discordo | AC12: Deveriam ter um setor para este tipo de atendimento/suporte aos funcionários | AD12: Concordo | AF12: Discordo | AH12: Concordo Sempre | AJ12: Concordo | AL12: Concordo Sempre | AN12: Concordo Sempre | AP12: Discordo | AQ12: As vezes sentimos falta desse diálogo diário, para que entendam as nossas necessidades | AR12: Concordo | AT12: Discordo | AU12: Falta de treinamentos específicos para a condução das nossas equipes | AV12: Concordo Sempre | AX12: Concordo | AZ12: Discordo | BA12: As vezes ficamos desenformados sobre as decisões estratégicas da empresa | BB12: Concordo | BD12: Concordo | BF12: Concordo | BH12: Concordo | BJ12: Concordo | BL12: Concordo | BN12: Concordo | BP12: Concordo | BR12: Concordo Sempre | BS12: É notório que nesta empresa se respeitam as diversidades | BT12: Discordo | BV12: Concordo | BX12: Concordo | BZ12: Concordo Sempre | CB12: Discordo | CD12: Concordo | CE12: Só precisam estar mais disponíveis a ouvir mais as sugestões | CF12: Concordo Sempre | CH12: Concordo | CJ12: Concordo Sempre | CL12: Concordo Sempre | CN12: Concordo | CP12: Discordo | CR12: Concordo Sempre | CT12: Concordo | CV12: Concordo Sempre | CW12: Ambiente descontraído e bom para se trabalhar | CX12: Auxílio Combustível, Multibenefícios Alimentação/ Refeição, Enxoval Maternidade, Seguro de Vida, Empréstimo Consignado | CY12: Estes benefícios irão fazer com que a empresa se torne uma referência no mercado | CZ12: Tem oportunidade de crescimento; Ambiente leve e descontraído; Empresa que valoriza as pessoas | DA12: No intuito de se tornar uma empresa melhor | DB12: Esta empresa está em crescimento e acreditamos que ela vai conseguir os seus objetivos, só que em paralelo deva melhorar os seus benefícios para que se torne uma empresa desejada para se trabalhar, valorizar a sua mão de obra pois é diferenciada e deve ser tratada diferente do mercado.
A13: 45687.353 | B13: Concordo | D13: Concordo | F13: Concordo | H13: Concordo | J13: Concordo | L13: Concordo | N13: Concordo | P13: Concordo | R13: Concordo | T13: Concordo | V13: Concordo | X13: Concordo | Z13: Concordo | AB13: Concordo | AD13: Concordo | AF13: Concordo | AH13: Concordo | AJ13: Concordo | AL13: Concordo | AN13: Concordo | AP13: Concordo | AR13: Concordo | AT13: Concordo | AV13: Concordo | AX13: Concordo | AZ13: Concordo | BB13: Concordo | BD13: Concordo | BF13: Concordo | BH13: Concordo | BJ13: Concordo | BL13: Concordo | BN13: Concordo | BP13: Concordo | BR13: Concordo | BT13: Discordo | BU13: Nunca | BV13: Concordo | BX13: Concordo | BZ13: Discordo | CB13: Discordo | CD13: Concordo | CF13: Concordo | CH13: Concordo | CJ13: Concordo | CL13: Concordo | CN13: Discordo | CP13: Discordo | CR13: Concordo | CT13: Concordo | CV13: Concordo | CW13: Bom | CX13: Assistência Médica, Assistência Odontológica, Auxílio Combustível, Refeição na Empresa, Cesta Básica | CY13: Ser mas valorizador | CZ13: Tudo éu acho bom na empresa não tenho que fala | DA13: Vale combustível | DB13: Gostaria muito do vale combustível
A14: 45687.354 | B14: Concordo | D14: Discordo | E14: Deveríamos receber mais fardamentos | F14: Concordo Sempre | G14: Pois estamos sempre em conjunto ajudando uns aos outros. | H14: Concordo Sempre | J14: Concordo Sempre | K14: Pois sempre estão nos dando oportunidades de aprender | L14: Concordo | N14: Concordo Sempre | P14: Discordo Sempre | Q14: O salário é abaixo do mercado, e algumas funções dentro da empresa deveria receber insalubridade e periculosidade pois trabalhamos com produtos altamente cancerígeno e com produtos químicos | R14: Concordo | T14: Concordo Sempre | U14: Pois todos se dispõe a ajudá-lo a desenvolver sua função e aprender um pouco mais sobre a mesma. | V14: Concordo | X14: Concordo | Z14: Concordo Sempre | AB14: Discordo | AC14: Deveria haver uma ouvidoria | AD14: Concordo | AF14: Concordo | AH14: Concordo | AJ14: Concordo Sempre | AL14: Concordo Sempre | AN14: Concordo Sempre | AP14: Concordo Sempre | AR14: Concordo Sempre | AT14: Concordo | AV14: Concordo Sempre | AX14: Concordo | AZ14: Concordo | BB14: Concordo | BD14: Concordo Sempre | BF14: Concordo | BH14: Concordo Sempre | BJ14: Concordo Sempre | BL14: Concordo | BM14: De acordo com sua função todos tem autonomia moderada | BN14: Concordo Sempre | BP14: Concordo Sempre | BR14: Concordo Sempre | BT14: Discordo | BU14: Pois ele sempre busca nos ajudar e nos compreender | BV14: Concordo | BX14: Concordo | BZ14: Concordo Sempre | CB14: Discordo | CD14: Concordo | CF14: Concordo | CH14: Concordo Sempre | CJ14: Concordo | CL14: Concordo | CN14: Concordo | CP14: Discordo | CR14: Concordo Sempre | CT14: Concordo | CV14: Concordo Sempre | CW14: Pois nós deixa a vontade para desenvolver nossa função | CX14: Assistência Médica, Multibenefícios Alimentação/ Refeição, Auxílio Educação, Seguro de Vida, Empréstimo Consignado, Day Off | CY14: Assistência médica é essencial pois todos estão exposto a sofrer algum acidente de trabalho | CZ14: - A empresa está sempre aberta a novas ideias - A empresa oferece plano de carreira e oportunidades a todos - Estão sempre disposto a ajudar | DA14: - Bonificação deveria ser para todos, pois todos tem participação em locações, toda função é essencial para obtermos as metas. - Deveria melhorar os material dos fardamentos e quantidade - Alguns EPI's poderiam ser melhorados ex, luvas para lavagem, respirador | DB14: .
A15: 45687.354 | B15: Concordo | C15: As pessoas sao muito expressivas e demonstram no ambiente de trabalho muito o sentimentos quando esta com raiva por assunto de trabalho ou vida pessoal e quando se preciaa fazer trabalhos internos ou falar com o proximo repassa no olhar | D15: Concordo | E15: Precisamos de melhoria com os aparelhos celulares por ser antigos | F15: Concordo | G15: Nem sempre | H15: Concordo | I15: Nem sempre todos pensam iguais | J15: Discordo | K15: Gostariamos de cursos com profissionais capacitados para assuntos de comércio, por muitas vezes as reuniões que se fazem para melhorar algo nao é focada apenas nesss assunto sendo abordado assuntos desnecessário ou ate mesmo constrangimento | L15: Concordo Sempre | N15: Concordo Sempre | P15: Concordo Sempre | R15: Concordo Sempre | S15: Um ramo no qual me sinto bem em fazer parte | T15: Concordo Sempre | V15: Concordo Sempre | W15: Todos aqui sao pessoas diferentes uns simpatizam mais que outros | X15: Concordo Sempre | Z15: Concordo Sempre | AB15: Concordo | AD15: Concordo | AE15: Ja saiu pessoas maravilhosas que acrescentavam e por motivos pessoais envolvidos quem estava treinando nao teve paciência enquanto a pessoa estava em tempo de aprendizado | AF15: Concordo Sempre | AH15: Concordo Sempre | AJ15: Concordo Sempre | AL15: Concordo | AM15: Demonstra porem algumas vezes nao nos sentimos ajudados quando necessitamos é muita justificativa de nao da certo dessa forma do que encontrar um meio melhor ja de cara. | AN15: Concordo Sempre | AP15: Concordo Sempre | AR15: Concordo Sempre | AT15: Discordo | AV15: Concordo | AX15: Concordo | AY15: Nem sempre | AZ15: Concordo Sempre | BB15: Concordo Sempre | BD15: Discordo | BF15: Concordo | BH15: Discordo | BJ15: Concordo | BL15: Discordo | BN15: Concordo | BP15: Concordo Sempre | BQ15: Chamada de atenção as vezes de forma que ele se expressa no olhar com uma furia | BR15: Concordo Sempre | BT15: Concordo | BU15: Ja presenciei formas de falar desnecessárias | BV15: Discordo | BW15: Nem sempre | BX15: Concordo | BZ15: Concordo Sempre | CB15: Concordo | CD15: Discordo | CF15: Concordo | CG15: Porem pouco contato na verdade quase nada | CH15: Concordo | CJ15: Concordo | CK15: As vezes so enxergam erros | CL15: Concordo | CN15: Concordo Sempre | CP15: Discordo | CR15: Concordo Sempre | CT15: Concordo | CV15: Concordo Sempre | CW15: . | CX15: Assistência Médica, Auxílio Combustível, Celular, Vale Alimentação, Auxílio Educação, Empréstimo Consignado | CY15: . | CZ15: O comprometimento com o funcionário A dinâmica mensais | DA15: Melhoria do vale combustível e alimentação | DB15: .
A16: 45687.355 | B16: Concordo | D16: Concordo | F16: Concordo Sempre | H16: Concordo Sempre | J16: Discordo | K16: Acredito que poderiam haver mais treinamentos que abrangem todos os setores. | L16: Discordo | N16: Concordo | P16: Discordo | Q16: Acredito que há cargos que os salários podem ser melhorados. | R16: Concordo | T16: Concordo Sempre | V16: Concordo | X16: Concordo | Z16: Concordo Sempre | AB16: Discordo Sempre | AC16: É necessário criação de um canal anônimo de comunicação. | AD16: Discordo | AF16: Concordo | AH16: Concordo | AJ16: Concordo Sempre | AL16: Concordo Sempre | AN16: Concordo Sempre | AP16: Concordo Sempre | AR16: Concordo Sempre | AT16: Concordo | AV16: Concordo | AX16: Concordo Sempre | AZ16: Concordo | BA16: Acredito que possa haver mais clareza em alguns processos. | BB16: Concordo | BD16: Concordo | BF16: Concordo | BH16: Concordo | BJ16: Concordo | BL16: Concordo | BN16: Concordo | BP16: Concordo | BR16: Concordo Sempre | BT16: Discordo | BV16: Concordo Sempre | BX16: Concordo | BZ16: Concordo | CA16: Acredito que outros setores como a manutenção deveriam ter comemoração de metas como outros setores tem. | CB16: Discordo | CD16: Concordo Sempre | CF16: Concordo Sempre | CH16: Concordo Sempre | CJ16: Concordo | CL16: Concordo Sempre | CN16: Concordo | CP16: Discordo | CR16: Concordo | CT16: Concordo Sempre | CV16: Concordo Sempre | CW16: - | CX16: Assistência Médica, Assistência Odontológica, Multibenefícios Alimentação/ Refeição, Gympass (Convênio Academias), Day Off | CY16: - | CZ16: União entre os setores, ambiente respeitoso com todos e gestores acessíveis. | DA16: Espaço físico, flexibilidade de horários e implementação de modelo de trabalho híbrido. | DB16: A implantação de gympass nos benefícios.
A17: 45687.357 | B17: Concordo | D17: Concordo Sempre | F17: Concordo | H17: Concordo | J17: Concordo | L17: Concordo | N17: Concordo Sempre | P17: Concordo | R17: Concordo | T17: Concordo Sempre | V17: Concordo Sempre | X17: Concordo | Z17: Concordo Sempre | AB17: Concordo | AD17: Concordo | AF17: Concordo Sempre | AH17: Concordo Sempre | AJ17: Concordo Sempre | AL17: Concordo Sempre | AN17: Concordo Sempre | AP17: Concordo Sempre | AR17: Concordo Sempre | AT17: Concordo | AV17: Concordo | AX17: Concordo Sempre | AZ17: Concordo | BB17: Concordo Sempre | BD17: Concordo | BF17: Concordo | BH17: Concordo Sempre | BJ17: Concordo Sempre | BL17: Concordo Sempre | BN17: Concordo Sempre | BP17: Concordo Sempre | BR17: Concordo Sempre | BT17: Discordo Sempre | BU17: Sempre fui tratado com muito respeito. | BV17: Concordo | BX17: Concordo Sempre | BZ17: Concordo Sempre | CB17: Discordo | CC17: As pessoas tem boas relações porque os chefes são acessíveis e tranquilos, mas não porque estão procurando promoção dessa forma. | CD17: Concordo Sempre | CF17: Concordo Sempre | CH17: Concordo Sempre | CJ17: Concordo Sempre | CL17: Concordo | CN17: Concordo | CO17: Acredito que todo lugar vai ter um pouco de fofoca. | CP17: Discordo | CQ17: No meu setor eu não vejo isso. | CR17: Concordo | CT17: Concordo | CV17: Concordo Sempre | CW17: Uma das melhores empresas em que trabalhei. | CX17: Assistência Médica, Auxílio Combustível, Vale Refeição, Vale Alimentação, Gympass (Convênio Academias) | CY17: Eu acho interessante um gympass | CZ17: Cultura da empresa é um ponto muito forte Diretores pacientes e acessíveis Bons colegas de trabalho | DA17: Acredito que plano de saúde poderia melhorar e descontar um pouco menos, só isso mesmo. | DB17: Só os parabéns pela pesquisa de clima.
A18: 45687.358 | B18: Concordo | D18: Concordo | F18: Discordo | G18: Na maioria das vezes algumas pessoas apenas fazem aquilo que é pedido ou que está acostumado, ao passar de qualquer responsabilidade rotineira já reclama. | H18: Concordo | I18: Hoje em dia a comunicação e a colaboração é melhor do que já foi a 1 ano, porém sinto falta de alguns colaboradores entenderem que todos os setores fazem a empresa acontecer e por isso todos independente da área de atuação precisam pensar no cliente e nos objetivos que temos para conseguirmos concluir nossas metas e objetivos. | J18: Discordo | K18: Sinto falta de um treinamento específico principalmente para novos colaboradores, nossa área de atuação é muito específica e muitas vezes o profissional não vem preparado e nem com o mínimo de conhecimentos sobre equipamentos, seria uma alternativa criar um tipo de treinamento sobre equipamentos para novos colaboradores. | L18: Concordo | N18: Concordo | P18: Discordo | Q18: Já melhorou bastante desde que abrimos a unidade, mas conhecendo o mercado ainda não chegamos no mesmo padrão salarial. | R18: Concordo Sempre | T18: Concordo Sempre | V18: Concordo | X18: Concordo | Z18: Concordo Sempre | AB18: Discordo | AC18: Normalmente quando precisamos sugerir ou reivindicar precisamos falar com o gerente da unidade, o que poderia acabar sobrecarregando com algo que poderia ser falado diretamente para os setores responsáveis. Seria interessante ser criado um tipo de canal de sugestões e idéias a qual os colaboradores poderiam dar sugestões de melhorias, fazer reivindicações e até expressar idéias. | AD18: Concordo Sempre | AF18: Concordo | AH18: Concordo Sempre | AJ18: Concordo Sempre | AK18: Em todas as conversas que temos ele sempre me instrui naquilo que espera e também almeja para mim profissionalmente, me dando sempre sugestões e feedbacks no que posso melhorar para ser uma boa profissional e crescer na empresa. | AL18: Concordo Sempre | AN18: Concordo Sempre | AP18: Concordo Sempre | AQ18: Em todas as vezes que precisei de ajuda com algo pessoal, ou fiquei doente ou algo relacionado, sempre vi que ele se mostrava prestativo em ajudar e genuinamente preocupado com meu bem estar. | AR18: Concordo Sempre | AT18: Concordo Sempre | AV18: Concordo Sempre | AX18: Concordo | AY18: Eu concordo, porém as vezes eu sinto falta de uma escuta mais ativa, sem interrupções e de tentar realmente entender o que estamos tentando explicar ou dar de idéia. | AZ18: Concordo Sempre | BB18: Concordo Sempre | BD18: Concordo Sempre | BF18: Concordo Sempre | BH18: Concordo | BJ18: Concordo Sempre | BL18: Concordo Sempre | BN18: Concordo Sempre | BP18: Concordo Sempre | BR18: Concordo | BT18: Discordo Sempre | BV18: Concordo | BX18: Discordo | BY18: Existe nos setores em específico, mas sinto falta do sentimento de equipe geral. | BZ18: Concordo Sempre | CB18: Discordo | CD18: Concordo | CE18: Temos fácil acesso para falar e até dar ideias, mas tenho a sensação de que as ideias não são genuinamente aceitas de forma positiva e nem ouvidas com atenção para tentar entender o que temos a dizer, como se o que dizemos até é ouvido no momento, mas logo após já é esquecido sem dar devida atenção. | CF18: Concordo | CH18: Concordo Sempre | CJ18: Concordo | CL18: Concordo Sempre | CN18: Discordo | CP18: Discordo Sempre | CR18: Concordo Sempre | CT18: Concordo | CU18: Há muita coisa pra melhorar ainda, mas já evoluímos bastante | CV18: Concordo Sempre | CW18: Nenhum lugar é perfeito, mas independente de tudo isso, a Nordeste é ótimo lugar para se trabalhar, gosto do meu trabalho e das pessoas com quem convivo mesmo com seus defeitos. | CX18: Assistência Médica, Auxílio Combustível, Multibenefícios Alimentação/ Refeição, Auxílio Educação, Gympass (Convênio Academias) | CY18: . | CZ18: Ambiente de trabalho, comunicação com a liderança e o reconhecimento aos colaboradores. | DA18: Melhoria na gestão de pessoas por parte da diretoria em relação a comunicação mais assertiva e escuta mais ativa, melhor suporte da parte administrativa (financeiro, contábil, comercial...), treinamentos específicos e bem organizados. | DB18: Nada mais a pontuar
A19: 45687.36 | B19: Concordo | D19: Discordo | E19: Agenda é fundamental para organização e planejamento do dia e ainda não recebemos. | F19: Concordo | G19: A maioria sim. | H19: Concordo | J19: Concordo | L19: Concordo | N19: Concordo | P19: Discordo | Q19: Diversas outras empresas do mesmo seguimento tem remunerações maiores, mas o que mais pesa na Nordeste realmente é bom relacionamento na empresa e com os seus diretores. | R19: Concordo | T19: Concordo | U19: O acolhimento da Nordeste realmente é diferenciado. | V19: Concordo | X19: Concordo | Z19: Concordo | AB19: Concordo | AC19: Concordo, mas na maioria das vezes em que são “deixadas” sugestões elas são rebatidas mostrando que não fazem sentido. | AD19: Concordo Sempre | AF19: Concordo Sempre | AH19: Concordo Sempre | AJ19: Concordo Sempre | AL19: Concordo Sempre | AN19: Concordo Sempre | AP19: Concordo | AR19: Concordo | AT19: Concordo Sempre | AV19: Concordo Sempre | AX19: Concordo | AZ19: Concordo | BB19: Concordo | BD19: Concordo Sempre | BF19: Discordo | BG19: Novas decisões ou diretrizes só são comunicadas. | BH19: Discordo | BI19: Depende muito do dia e da situação. | BJ19: Discordo | BK19: É um processo de construção constante, mas existe bastante divergência. | BL19: Concordo Sempre | BN19: Discordo | BO19: Há muita divergência. | BP19: Concordo Sempre | BR19: Concordo | BT19: Concordo | BU19: Existem algumas piadas com terceiros sim | BV19: Concordo | BX19: Concordo Sempre | BZ19: Concordo Sempre | CB19: Discordo Sempre | CC19: Não presenciei. | CD19: Concordo Sempre | CF19: Concordo Sempre | CH19: Concordo Sempre | CJ19: Concordo | CL19: Concordo | CN19: Concordo Sempre | CP19: Discordo | CQ19: A empresa trabalha muito em equipe. | CR19: Concordo Sempre | CT19: Concordo | CV19: Concordo | CW19: Sim é um lugar para se trabalhar | CX19: Assistência Médica, Assistência Odontológica, Multibenefícios Alimentação/ Refeição, Auxílio Educação, Seguro de Vida, Gympass (Convênio Academias), Day Off | CY19: Nada a complementar. | CZ19: Organização, bom relacionamento entre setores, bom relacionamento com os diretores | DA19: Treinamento e desenvolvimento, espaço de trabalho, salário compatível com o mercado. | DB19: Nada a complementar.
A20: 45687.36 | B20: Concordo | C20: . | D20: Concordo | E20: . | F20: Discordo | G20: Pessoal acomodado , so faz o basico fico um pouco preocupado em relaçao a isso !! | H20: Concordo | I20: Porém, para fazer alguma atividades que cabe ao mesmo é preciso que chame ! | J20: Concordo | K20: . | L20: Concordo | M20: Sim, e estou buscando melhoras para crescer junto com a empresa!! | N20: Discordo | O20: Nossos lideres nao reconhece !! | P20: Concordo | R20: Concordo | S20: Gosto do que faço!! | T20: Concordo | V20: Discordo | W20: Eu sou grato pro alguma coisas mais nao tenho orgulho nao , pessoas tende a Ser Falsas | X20: Concordo | Z20: Discordo | AA20: Algumas coisas me deixam na obrigaçao de participar, nao e do meu perfil certas coisas que aqui vejo ou faço! | AB20: Concordo | AC20: O unico canal para esse tipo de situaçao é essa pesquisa de clima e eu espero que realmente fucione! | AD20: Concordo | AE20: Eu acredito, nosso segmento é instavel e sao cheio de supresas !! | AF20: Discordo | AG20: Nao me lembro de ninguem aqui me encorajar am nada ! | AH20: Discordo | AI20: Nao sei .. | AJ20: Discordo | AK20: Nao , muitas falhas na LINDERÇA | AL20: Discordo | AM20: Nao vejo ele comentando muito sobre isso nao !! | AN20: Concordo | AO20: . | AP20: Concordo | AR20: Concordo | AS20: Porem devido algumas falha dele , as conversas e reividicaçoes nao sao cumpridas . | AT20: Discordo | AU20: Nao , nao vejo isso aqui. | AV20: Concordo | AW20: . | AX20: Concordo | AY20: Nao é sempre ! | AZ20: Concordo | BA20: . | BB20: Concordo | BC20: . | BD20: Concordo | BE20: Sim, mais é necessario que haja um acompanhamento , ja que se faz necessario !! | BF20: Concordo | BG20: . | BH20: Discordo | BI20: Ha sempre uma que tem um tratamento diferente ! | BJ20: Discordo | BK20: Muitas falhas nesse tipo de tarefa! | BL20: Concordo | BM20: . | BN20: Discordo | BO20: Nao , fala mais nao faz !! | BP20: Concordo | BQ20: . | BR20: Concordo | BS20: . | BT20: Concordo | BU20: . | BV20: Discordo | BW20: Nao , nao vou generalizar mais muitas aqui nao tem sentimos pelos outros !! | BX20: Discordo | BY20: Muita idividualismo. | BZ20: Concordo | CA20: . | CB20: Concordo | CC20: So so fazem escondido! | CD20: Concordo | CE20: . | CF20: Discordo | CG20: Nao , ainda fexados para alguns assuntos | CH20: Concordo | CI20: . | CJ20: Concordo | CK20: . | CL20: Concordo | CM20: . | CN20: Concordo | CO20: Muita, bastante muitas vezes parte ate de pessoas a Cima de voce | CP20: Concordo | CQ20: Vejo sim, e isso me encomoda | CR20: Concordo | CS20: Tenho certeza que boas coisas estao por vim.. | CT20: Discordo | CU20: Nao , vejo muito cada um no seu !! | CV20: Concordo | CW20: Com alguma coisas a serem corregidas , mais sim digo que é um bom lugar pra trabalhar !! | CX20: Assistência Médica, Auxílio Combustível, Vale Alimentação, Auxílio Educação, Day Off | CY20: . | CZ20: Comprpmisso, atençao com colaborador, e abertas a ideias . | DA20: Mais firmeza dos lideres e compromisso por parte da alguns colabordores . | DB20: .
A21: 45687.36 | B21: Concordo | C21: Eu gosto do meu ambiente de trabalho, pois me sinto beme me sinto leve para realizar minhas atividades | D21: Concordo | E21: Todos os equipamentos que preciso tenho para realizar meu trabalho | F21: Concordo | G21: Sim com certeza | H21: Concordo | I21: Sim | J21: Concordo | K21: Sim | L21: Concordo | M21: Sim com certeza | N21: Concordo | O21: Sim | P21: Discordo | Q21: Não | R21: Concordo Sempre | S21: Sim, pois o meu trabalho tem um grande significado pra mim, e não e só mais um trabalho | T21: Concordo | U21: Sim, sempre fazemos apresentação | V21: Concordo | W21: Sim | X21: Concordo | Y21: Sim | Z21: Concordo | AA21: Me sinto bem no meu ambiente de trabalho, pois não me sinto afadigado com minhas atividades, e não preciso fingir ser alguém que não sou | AB21: Discordo | AC21: Não | AD21: Concordo | AE21: ... | AF21: Concordo | AH21: Concordo | AI21: Sim, sei quem e meu líder | AJ21: Concordo | AK21: Sei o que ele espera, ele espera resultados positivos, eficiência e agilidade no trabalho | AL21: Concordo | AM21: Sempre uma pessoa comprometida com o trabalho, interessado, e empenhado com o crescimento 📈 da empresa e tem uma visão clara do futuro e sabe o que quer para si, e para os demais | AN21: Concordo | AO21: Meu líder e honesto, tem uma boa conduta, um bom caráter para lidar com os negócios da empresa e sempre e transparente | AP21: Concordo | AQ21: Meu líder não só me vê como um simples funcionário, pois me vê além do que um funcionário, pois me vê como um um amigo e não só como funcionário | AR21: Concordo | AS21: Sim, pois o que precisamos o que ele sempre está aqui pra nós estender a mão e propor soluções para cada tipo de situação | AT21: Concordo | AU21: Sim, sempre nos instrui nos mostrando o caminho certo para o que devemos fazer, onde estamos errando para que não erre mais, como um bom pastor que guia as ovelhas | AV21: Concordo | AX21: Concordo | AY21: Sim, pois sempre está apto para ouvir nossas ideias de melhoria e sempre melhora nossas ideias | AZ21: Concordo | BA21: Sim pois todos os assuntos que nos convém saber ele está sempre nos deixando por dentro sempre | BB21: Concordo | BD21: Concordo | BE21: Sim, pois ele confia no nosso trabalho isso e o que um elo de confiança que temos, confiança e base de tudo sem isso o trabalho não rende, o trabalho não sai legal então confiança e tudo | BF21: Concordo | BH21: Concordo | BI21: Sim, pois ele não passa a mão na cabeça de ninguém, pois ele prática a justiça ⚖️♎ para todos | BJ21: Concordo | BL21: Concordo | BM21: Sim, vejo meu linder dar autonomia para as pessoas, eu acho isso muito importante | BN21: Concordo | BO21: Sim, pois age da forma como fala | BP21: Concordo | BQ21: Ele está sempre dando feedback, tá sempre chamando a gente pra dar opinião, falando como podemos agir pra melhorar como funcionário | BR21: Concordo | BT21: Discordo | BV21: Discordo | BX21: Concordo | BY21: Sim,. existe pois estamos sempre tentando ajudar uns aos outros | BZ21: Concordo | CA21: Sim, pois eu só acho que devíamos melhorar um pouco no valor, pois acho muito pouco para nossa região | CB21: Discordo | CC21: Discordo pois não vejo isso entre nós | CD21: Concordo | CF21: Concordo | CG21: ... | CH21: Concordo | CI21: Sou sim, independente da minha posição de trabalho | CJ21: Concordo | CK21: ... | CL21: Concordo | CM21: Sim, pois meu lugar de trabalho e bom pra trabalhar e leve | CN21: Concordo | CO21: ... | CP21: Discordo | CQ21: Não vejo entre nós | CR21: Concordo | CS21: Sim com certeza por muito tempo se Deus permitir | CT21: Discordo | CU21: .... | CV21: Concordo | CW21: Sim concordo plenamente | CX21: Assistência Médica, Celular, Refeição na Empresa, Seguro de Vida, Empréstimo Consignado, Gympass (Convênio Academias) | CY21: .. | CZ21: Reconhecimento profissional. Benefícios ... | DA21: Eu acho que devíamos ter uma ouvidoria para ouvir nossas queixas reclamações, acho que e importante em questão ao salário e pago muito tarde eu acho que seja um ponto de melhoria para melhorara e pagar pela manhã | DB21: Eu acho que deviam ser pergunta melhores, e menos perguntas pois tem muitas perguntas
A22: 45687.36 | B22: Concordo | D22: Concordo | F22: Concordo | H22: Concordo | J22: Concordo | L22: Concordo | N22: Concordo | P22: Discordo | Q22: Salários um pouco a baixo do mercado, incluindo ticket. | R22: Concordo | T22: Concordo | V22: Concordo | X22: Discordo | Y22: Falando por mim próprio, eu sempre venho com vontade e disposição para trabalhar, os meus colegas eu já não sei, aparentemente sim, alguns. | Z22: Concordo | AB22: Concordo | AC22: Na unidade de São Luís o gestor está sempre aberto a ouvir os colaboradores e sempre fazendo feedbacks para tratar assuntos de melhorias para a equipe. | AD22: Concordo Sempre | AF22: Concordo | AH22: Concordo | AJ22: Concordo | AL22: Concordo | AN22: Concordo | AP22: Concordo | AR22: Concordo | AT22: Concordo | AV22: Concordo | AX22: Concordo | AZ22: Concordo | BB22: Concordo | BD22: Discordo | BE22: Em partes sim em partes não, muitas vezes tem aquela olhada no sistema de monitoramento, mas nada prejudicial. Acredito que seja normal em todas as empresas. | BF22: Discordo | BH22: Concordo | BJ22: Concordo | BL22: Concordo | BN22: Concordo | BP22: Concordo | BR22: Concordo | BT22: Discordo Sempre | BV22: Concordo | BX22: Concordo | BZ22: Concordo | CB22: Discordo | CD22: Concordo | CF22: Concordo | CH22: Concordo | CJ22: Concordo | CL22: Concordo | CN22: Concordo | CP22: Discordo | CR22: Concordo Sempre | CT22: Concordo | CV22: Concordo | CW22: Ambiente legal, com pessoas boas, competentes, companheiras, etc. | CX22: Assistência Médica, Auxílio Combustível, Multibenefícios Alimentação/ Refeição, Seguro de Vida, Day Off | CY22: Poderia ter mais que cinco opções! | CZ22: Reconhecimento de profissionais, ambiente leve, valorização. | DA22: Valorização de salários, valorização de ticket, treinamentos adequados com nossas marcas parceiras (todas). | DB22: Nada além do que já foi observado nos comentários.
